Workbook
Name ASSESSMENT_1: 'Bewertung - Assessment'!$E$4:$E$166
Name ASSESSMENT_2: 'Bewertung - Assessment'!$I$4:$I$166
Name ASSESSMENT_3: 'Bewertung - Assessment'!$M$4:$M$166
Name RISK_ASSESSMENT: 'Bewertung - Assessment'!$Q$4:$Q$166

Sheet Guide
A2: Kriterien für die Bewertung des Risikos bei Nicht-Dokumentation
A3: 1 | B3: FuSi relevanter Punkt. Weil nicht vom Safety Concept abgedeckt und damit keine entsprechenden Maßnahmen und damit die dort adressierten Probleme erwartet werden müssen. STATUS: 4
A4: 2 | B4: Punkte die zur Bestimmung der notwendigen Performance und Resourcenverbrauch notwendig sind (z.b. reicht der Arbeitsspeicher?). Hier müsste im worst case die Soft- und/oder Hardware neu dimensioniert werden. STATUS: 3
A5: 3 | B5: Punkte die sich eher auf Organisation und Zuständigkeiten (Ansprechpartner, Zuständigkeiten, Entwicklungsumgebung) beziehen. Hier kann üblicherweise davon ausgegangen werden, dass deren Dokumentation Kommunikation und Organisation erleichtern, sie aber grundsätzlich in einem Projekt implizit bekannt sind bzw. bereits existieren. STATUS: 1 oder 2
A6: 4 | B6: Punkte, die sich auf detaillierte Beschreibungen von bereits generell gemachten Designentscheidungen beziehen. Z.b. die Angabe aller Variablen im RAM wenn bereits die Größe der einzelnen Stacks dokumentiert ist. Hier würde ich davon ausgehen, dass das zum einen vor Start der Implementierung schwer anzugeben ist und zum anderen üblicherweise eher Abschätzungen auf Basis von Erfahrungen zum Einsatz kommen. STATUS: 2
A7: 5 | B7: Wiedergabe von Eigenschaften von Standard HW/SW Komponenten die ggf. in den Dokumentationen der Komponenten angegeben sind. Z.B. Beschreibung der MCU wenn der genaue Hersteller und Typ bereits dokumentiert ist. Hier sind die Details hilfreich für das Review und die Angabe zeigt, dass der Zulieferer sich ebenfalls damit beschäftigt hat und sie kennt und berücksichtigt. Im allgemeinen würde ich aber davon ausgehen, dass das der Fall ist. STATUS: 1 oder 2

Sheet Titel
B1: Version | C1: R08
B3: SWAD Review - Review of Software Architecture Documentation
B4: Runde / Iteration | C4: 2
B5: ECU Name / Product | C5: SV62 MCU
B6: Lieferant / Supplier | C6: TTTech Auto
B7: Model Series / Baureihe
B8: Leitfaden SWAD / Guideline SWAD | C8: v5.1
B11: Bereitgestellte Dokumente / Provided Documents
B12: Runde / Iteration | C12: Dokument / Document | F12: Lieferdatum / Delivery Date | G12: Referenz / Reference | H12: Inhalt / Content
B13: 1 | C13: SV62_MCU_Platform_Software_Architecture_Report_v0.2.pdf | F13: 45751 | G13: [1] | H13: SV62 MCU Software Architecture
B14: 2 | C14: SV62_MCU_Platform_Software_Architecture_Report_v0.3.pdf | F14: 45795 | G14: [2] | H14: SV62 MCU Software Architecture
B15: 2 | C15: schedule_visualization_SH.html | F15: 45795 | G15: [3] | H15: Safety Host schedule visualization
B16: 2 | C16: schedule_visualization_PH.html | F16: 45795 | G16: [4] | H16: Performance Host schedule visualization
B26: Legende: Bewertung Abweichung der Dokumentation ggü. Leitfaden / Legend: Assessment of Deviations with respect to Documentation Requirements in "Leitfaden"
B27: 0 | C27: => n/a
B28: 1 | C28: => ok
B29: 2 | C29: => geringe Abweichung / minor deviation
B30: 3 | C30: => mittlere Abweichung / moderate deviation
B31: 4 | C31: => große Abweichung oder nicht vorhanden / major deviation or missing
K33: =_xlfn.CONCAT("Bewertung / Assessment: Round ",B36) -> Bewertung / Assessment: Round 1
B34: Ergebnis Statistik / Result Statistics | K34: Overall Status: | M34: RED
B35: Runde / Iteration | C35: Gesamtanzahl/ Total number | D35: 0 | E35: 1 | F35: 2 | G35: 3 | H35: 4 | K35: - Architecture document covers most of the technical concepts regarding Logical and Conceptual view. Provided document is compliant to ASPICE requirements. - However, there are 64 out of 133 points not documented and missing information required as per Porsche architecture document guideline. - Almost all points in chapter ISRs, OS-Hooks for AUTOSAR OS and OS Services for POSIX OS are missing. - Several minor to moderate deviations are due to insufficient information on requested aspects.
B36: 1 | C36: =COUNTA(ASSESSMENT_1) -> 134 | D36: =COUNTIF(ASSESSMENT_1,D$35) -> 1 | E36: =COUNTIF(ASSESSMENT_1,E$35) -> 20 | F36: =COUNTIF(ASSESSMENT_1,F$35) -> 9 | G36: =COUNTIF(ASSESSMENT_1,G$35) -> 8 | H36: =COUNTIF(ASSESSMENT_1,H$35) -> 96
B37: 2 | C37: =COUNTA(ASSESSMENT_2) -> 134 | D37: =COUNTIF(ASSESSMENT_2,D$35) -> 8 | E37: =COUNTIF(ASSESSMENT_2,E$35) -> 56 | F37: =COUNTIF(ASSESSMENT_2,F$35) -> 21 | G37: =COUNTIF(ASSESSMENT_2,G$35) -> 7 | H37: =COUNTIF(ASSESSMENT_2,H$35) -> 42
B38: 3 | C38: =COUNTA(ASSESSMENT_3) -> 0 | D38: =COUNTIF(ASSESSMENT_3,D$35) -> 0 | E38: =COUNTIF(ASSESSMENT_3,E$35) -> 0 | F38: =COUNTIF(ASSESSMENT_3,F$35) -> 0 | G38: =COUNTIF(ASSESSMENT_3,G$35) -> 0 | H38: =COUNTIF(ASSESSMENT_3,H$35) -> 0
B61: Risiko Einstufung / Risk Assessment
B62: Level | C62: 0 | D62: 1 | E62: 2 | F62: 3 | G62: 4 | H62: -
C63: keine Risiken / no risks | G63: hohe Risiken / high risks
C64: =COUNTIF(RISK_ASSESSMENT,C$62) -> 0 | D64: =COUNTIF(RISK_ASSESSMENT,D$62) -> 0 | E64: =COUNTIF(RISK_ASSESSMENT,E$62) -> 0 | F64: =COUNTIF(RISK_ASSESSMENT,F$62) -> 0 | G64: =COUNTIF(RISK_ASSESSMENT,G$62) -> 0
B66: Default Risiko Einstufung bei fehlender Dokumentation / Default Risk Assessment in case of Missing Documentation | K66: =_xlfn.CONCAT("Bewertung / Assessment: Round ",B37) -> Bewertung / Assessment: Round 2
B67: Level | C67: D0 | D67: D1 | E67: D2 | F67: D3 | G67: D4 | H67: - | K67: Overall Status: | M67: RED
C68: keine Risiken / no risks | G68: hohe Risiken / high risks | K68: - The architecture document has been extended with information on scheduling and the memory map. Other chapters with a rating of 2 or higher have not been updated. - Currently, 70 out of 133 points are not documented and missing information required as per Porsche architecture review guideline. - However, the completeness of the architecture document has increased from 16% in Round 1 to 48% in Round 2. - Almost all points in the chapters on ISRs, OS Hooks for AUTOSAR OS, and OS-Services for POSIX OS are missing. - Several minor to moderate deviations are due to insufficient information on requested aspects.
C69: =COUNTIF(RISK_ASSESSMENT,C$67) -> 3 | D69: =COUNTIF(RISK_ASSESSMENT,D$67) -> 1 | E69: =COUNTIF(RISK_ASSESSMENT,E$67) -> 7 | F69: =COUNTIF(RISK_ASSESSMENT,F$67) -> 26 | G69: =COUNTIF(RISK_ASSESSMENT,G$67) -> 5

Sheet Bewertung - Assessment
B2: Leitfaden / Guideline | C2: Leitfaden Software Architektur Dokumentation (Kapitel-Referenz in Spalte B bezieht sich auf das Leitfaden-Dokument) | D2: Guideline Software Architecture Documentation (Chapter-Reference in Column B refers to the guideline document) | E2: Runde 1 / Iteration 1 | H2: 1 | I2: Runde 2 / Iteration 2 | L2: 2 | M2: Runde 3 / Iteration 3 | P2: 3
A3: Leitfaden Version/ Guideline Version | B3: Kapitel / Chapter | C3: Review Gegenstand | D3: Review Objects | E3: Kurzbewertung / Short Assessment | F3: Referenz / Reference | G3: Kommentar / Comment | I3: Kurzbewertung / Short Assessment | J3: Referenz / Reference | K3: Kommentar / Comment | M3: Kurzbewertung / Short Assessment | N3: Referenz / Reference | O3: Kommentar / Comment | Q3: Risiko / Risk | R3: Default Risiko / Default Risk
A4: 4.5, 4.6, 5.1 | B4: 3 | C4: Deckblatt | D4: Cover Sheet
A5: 4.5, 4.6, 5.1 | B5: 3 | C5: Steuergerät | D5: Control unit | E5: 1 | F5: [1] Header | G5: SV62 MCU | I5: 1 | J5: [2] Header | K5: SV62 MCU | Q5: =IF(OR(ISBLANK(I5),I5="4"),'Bewertung - Assessment'!R5,Titel!H$67) -> - | R5: D0
A6: 4.5, 4.6, 5.1 | B6: 3 | C6: Zielbaureihe | D6: Target Product Line | E6: 4 | G6: not documented | I6: 4 | K6: no change | Q6: =IF(OR(ISBLANK(I6),I6="4"),'Bewertung - Assessment'!R6,Titel!H$67) -> D0 | R6: D0
A7: 5.1 | B7: 3 | C7: Fahrzeugarchitektur | D7: Vehicle Architecture | E7: 4 | G7: not documented | I7: 4 | K7: no change | Q7: =IF(OR(ISBLANK(I7),I7="4"),'Bewertung - Assessment'!R7,Titel!H$67) -> D0 | R7: D0
A8: 4.5, 4.6, 5.1 | B8: 3 | C8: Weitere Baureihen und/oder Fahrzeugarchitekturen mit geplantem Einsatz | D8: Other future product lines and/or vehicle architecture with planned deployment | E8: 4 | G8: not documented | I8: 0 | K8: NA | Q8: =IF(OR(ISBLANK(I8),I8="4"),'Bewertung - Assessment'!R8,Titel!H$67) -> - | R8: D0
A9: 4.5, 4.6, 5.1 | B9: 3 | C9: Autor und Ansprechpartner | D9: Author and contact person | E9: 4 | G9: not documented | I9: 4 | K9: no change | Q9: =IF(OR(ISBLANK(I9),I9="4"),'Bewertung - Assessment'!R9,Titel!H$67) -> D0 | R9: D0
A10: 4.5, 4.6, 5.1 | B10: 3 | C10: Datum | D10: Date | E10: 1 | F10: [1] Revision History | G10: 45737 | I10: 1 | J10: [2] Revision History | K10: 45793 | Q10: =IF(OR(ISBLANK(I10),I10="4"),'Bewertung - Assessment'!R10,Titel!H$67) -> - | R10: D0
A11: 4.5, 4.6, 5.1 | B11: 3 | C11: Version | D11: Version | E11: 1 | F11: [1] Revision History | G11: version 0.2 | I11: 1 | J11: [2] Revision History | K11: version 0.3 | Q11: =IF(OR(ISBLANK(I11),I11="4"),'Bewertung - Assessment'!R11,Titel!H$67) -> - | R11: D0
A12: 4.5, 4.6, 5.1 | B12: 3 | C12: Technische Randbedingungen | D12: Technical marginal conditions
A13: 4.5, 4.6, 5.1 | B13: 3 | C13: - Klemmenversorgung (Klemme 15 oder 30) | D13: - Terminal supply (terminal 15 or 30) | E13: 2 | F13: [1] 6.1 Overall ECU start-up | G13: KL30? Not mentioned explicitly anywhere | I13: 2 | J13: [2] 6.1 Overall ECU start-up | K13: KL30? Not mentioned explicitly anywhere | Q13: =IF(OR(ISBLANK(I13),I13="4"),'Bewertung - Assessment'!R13,Titel!H$67) -> - | R13: D1
A14: 4.5, 4.6, 5.1 | B14: 3 | C14: - Genutzte Busse | D14: - Communication buses used | E14: 1 | F14: [1] 5.2.1 Communication | G14: CAN, Ethernet, I2C, UART | I14: 1 | J14: [2] 5.2.1 Communication | K14: CAN, Ethernet, I2C, UART | Q14: =IF(OR(ISBLANK(I14),I14="4"),'Bewertung - Assessment'!R14,Titel!H$67) -> - | R14: D1
A15: 4.5, 4.6, 5.1 | B15: 3 | C15: - Eingesetztes OS (Hersteller, Name, Version) | D15: - Deployed operating systems (supplier, name, version) | E15: 2 | F15: [1] 3.2.2 Platform Software View | G15: Classic Autosar & POSIX OS (QNX RTOS) '- missing supplier, version ... | I15: 2 | J15: [2] 3.2.2 Platform Software View | K15: - Classic Autosar & POSIX OS (QNX RTOS) - 8 x Cortex A53: Performance host (QNX) - 3 x Cortex M7: Safety Host (Classic Autosar) - missing supplier, version ... - "Classic AutoSar -->Vector Microsar OS S32G v2.88, QNX OS version 7.1 from blackberry" - shall be added in arch docu. | Q15: =IF(OR(ISBLANK(I15),I15="4"),'Bewertung - Assessment'!R15,Titel!H$67) -> - | R15: D1
A16: 4.5, 4.6, 5.1 | B16: 3 | C16: - Eingesetzte MCU(s), verfügbarer RAM, ROM, EEPROM | D16: - Used MCU(s), available RAM, ROM, EEPROM | E16: 2 | F16: [1] | G16: S32G3 SoC '- missing RAM, ROM, EEPROM size - S.NOR Flash 256 MB - eMMC 64 GB | I16: 2 | J16: [2] 6.2.14 Memory Layout 5.2.14.4 Memory Peripheral Tests | K16: S32G3 SoC '- SRAM, ROM, EEPROM size - LPDDR4 4 GB - S.NOR Flash 256 MB (Safety host) - eMMC 64 GB (Performance host) | Q16: =IF(OR(ISBLANK(I16),I16="4"),'Bewertung - Assessment'!R16,Titel!H$67) -> - | R16: D1
A17: 4.5, 4.6, 5.1 | B17: 3 | C17: - Eingesetzte Flashbootloader (Hersteller, Name, Version) | D17: - Used Flash bootloader (supplier, name, version) | E17: 4 | G17: not documented | I17: 2 | K17: Vector FBL for VAG (license number: CBD2301386_D00) - should be documented in Arch. Docu. | Q17: =IF(OR(ISBLANK(I17),I17="4"),'Bewertung - Assessment'!R17,Titel!H$67) -> - | R17: D1
A18: 4.5, 4.6, 5.1 | B18: 3 | C18: Spezielle Anforderungen | D18: Special requirements
A19: 4.5, 4.6, 5.1 | B19: 3 | C19: - Maximaler FuSi-Level des Systems | D19: - Maximum FuSa level of the system | E19: 3 | G19: max ASIL Rating? ASIL-D? | I19: 1 | J19: [2] chapter 6.2.13.1 | K19: ASIL-D | Q19: =IF(OR(ISBLANK(I19),I19="4"),'Bewertung - Assessment'!R19,Titel!H$67) -> - | R19: D1
A20: 4.5, 4.6, 5.1 | B20: 3 | C20: - Besondere Securityanforderungen (Komponentenschutz, SWaP, Flashdatensicherheit) | D20: - Special Security requirement (component protection, SWaP, flash data security) | E20: 1 | F20: [1] 5.2.13 Security 6.2.12 Security | I20: 1 | J20: [2] 5.2.13 Security 6.2.12 Security | Q20: =IF(OR(ISBLANK(I20),I20="4"),'Bewertung - Assessment'!R20,Titel!H$67) -> - | R20: D1
A21: 4.5, 4.6, 5.1 | B21: 3 | C21: - OBD-Relevanz | D21: - OBD relevance | E21: 1 | F21: [1] | G21: yes | I21: 1 | J21: [2] chapter 6.2.4, 5.2.4 Diagnostics | Q21: =IF(OR(ISBLANK(I21),I21="4"),'Bewertung - Assessment'!R21,Titel!H$67) -> - | R21: D1
A22: 4.5, 4.6, 5.1 | B22: 3 | C22: - Teilnahme am Teilnetzbetrieb (aktiv, passiv, keine) | D22: - Participation in the sub network operation (active, passive, none) | E22: 1 | F22: [1] 5.2.1.1.1 Signal oriented communication | G22: - SH master, PF Slave on ethernet - CAN on SH | I22: 1 | J22: [2] 5.2.1.1.1 Signal oriented communication | K22: - SH master, PF Slave on ethernet - CAN on SH | Q22: =IF(OR(ISBLANK(I22),I22="4"),'Bewertung - Assessment'!R22,Titel!H$67) -> - | R22: D1
A23: 4.5, 4.6, 5.1 | B23: 3 | C23: - Diagnoseklasse | D23: - Diagnosis class | E23: 4 | G23: which diagnosis class | I23: 2 | K23: D4 High - shall be documented | Q23: =IF(OR(ISBLANK(I23),I23="4"),'Bewertung - Assessment'!R23,Titel!H$67) -> - | R23: D1
A24: 4.5, 4.6, 5.1 | B24: 4 | C24: Konzeptionelle Sicht | D24: Conceptual View
A25: 4.5, 4.6, 5.1 | B25: 4.1 | C25: Überblick | D25: Overview | E25: 1 | F25: [1] 5.1 Level 1: High-level building blocks 7.2 S32G3 device deployment 3.1 Business Context 3.3 Use Cases | I25: 1 | J25: [2] 5.1 Level 1: High-level building blocks 7.2 S32G3 device deployment 3.1 Business Context 3.3 Use Cases | Q25: =IF(OR(ISBLANK(I25),I25="4"),'Bewertung - Assessment'!R25,Titel!H$67) -> - | R25: D2
A26: 4.5, 4.6, 5.1 | B26: 4.2 | C26: Übernahme und Weiterentwicklung auf Basis anderer Projekte | D26: Takeover and Further Development Based on Other Projects | E26: 3 | F26: [1] 1 Introduction and Goals 2 Architecture Constraints | G26: It seems that some concepts are reused from HCP2.low project but not clear to what extent. It shall be described as per Leitpfaden. | I26: 3 | J26: [2] 1 Introduction and Goals 2 Architecture Constraints | K26: no change | Q26: =IF(OR(ISBLANK(I26),I26="4"),'Bewertung - Assessment'!R26,Titel!H$67) -> - | R26: D2
A27: 4.5, 4.6, 5.1 | B27: 4.3 | C27: Einsatz neuer Technologien oder Konzepte | D27: Use of New Technologies or Concepts | E27: 4 | G27: not documented | I27: 4 | K27: no change | Q27: =IF(OR(ISBLANK(I27),I27="4"),'Bewertung - Assessment'!R27,Titel!H$67) -> D3 | R27: D3
A28: 4.5, 4.6, 5.1 | B28: 4.4 | C28: Kritische architektur-relevante Anforderungen | D28: Critical Architectural Requirements | E28: 4 | G28: not documented | I28: 4 | K28: no change | Q28: =IF(OR(ISBLANK(I28),I28="4"),'Bewertung - Assessment'!R28,Titel!H$67) -> D3 | R28: D3
A29: 4.5, 4.6, 5.1 | B29: 4.5 | C29: Safety-relevante Aspekte | D29: Functional safety related aspects | E29: 3 | F29: [1] 8.1 High level Safety Concept | G29: which concrete safety goal needs to be achieved? | I29: 3 | J29: [2] 8.1 High level Safety Concept | K29: no change | Q29: =IF(OR(ISBLANK(I29),I29="4"),'Bewertung - Assessment'!R29,Titel!H$67) -> - | R29: D4
A30: 4.5, 4.6, 5.1 | B30: 4.6 | C30: Security-relevante Aspekte | D30: Security related aspects | E30: 1 | F30: [1] 5.2.13 Security 6.2.12 Security | I30: 1 | J30: [2] 5.2.13 Security 6.2.12 Security | Q30: =IF(OR(ISBLANK(I30),I30="4"),'Bewertung - Assessment'!R30,Titel!H$67) -> - | R30: D4
A31: 4.5, 4.6, 5.1 | B31: 4.7 | C31: Systemschnittstellen | D31: System interfaces | E31: 2 | F31: [1] pg.10, pg 35 | G31: - diagnostics, MotionWise Tool suite, Diagnostics Client tools (ODIS, PASDT), Command line tool '- List of interfaces in a table and how/when certain functionality is deactivated in production SW ECU? | I31: 2 | J31: [2] pg.10, pg 35 | K31: no change | Q31: =IF(OR(ISBLANK(I31),I31="4"),'Bewertung - Assessment'!R31,Titel!H$67) -> - | R31: D3
A32: 4.5, 4.6, 5.1 | B32: 4.8 | C32: Systemverhalten im Netzwerk | D32: Network dependencies / roles | E32: 1 | F32: [1] 5.2.1.1 Inter-ECU Communication 5.2.1.1.1 Signal oriented communication 5.2.1.1.2 Service oriented communication 5.2.1.1.3 REM Network Proxy 6.2.2.7 Wakeup via CAN | G32: - SH master, PF Slave on ethernet - CAN on SH | I32: 1 | J32: [2] 5.2.1.1 Inter-ECU Communication 5.2.1.1.1 Signal oriented communication 5.2.1.1.2 Service oriented communication 5.2.1.1.3 REM Network Proxy 6.2.2.7 Wakeup via CAN | K32: - SH master, PF Slave on ethernet - CAN on SH | Q32: =IF(OR(ISBLANK(I32),I32="4"),'Bewertung - Assessment'!R32,Titel!H$67) -> - | R32: D3
A33: 4.5, 4.6, 5.1 | B33: 4.9 | C33: Flexray-Betrieb | D33: Flexray | E33: 0 | G33: NA | I33: 0 | K33: NA | Q33: =IF(OR(ISBLANK(I33),I33="4"),'Bewertung - Assessment'!R33,Titel!H$67) -> - | R33: D2
A34: 4.5, 4.6, 5.1 | B34: 4.10 | C34: Software Updates | D34: ECU software updated | E34: 1 | F34: [1] 6.2.2.6 Update UDS 6.2.6 Software update | I34: 1 | J34: [2] 6.2.2.6 Update UDS 6.2.6 Software update | Q34: =IF(OR(ISBLANK(I34),I34="4"),'Bewertung - Assessment'!R34,Titel!H$67) -> - | R34: D2
A35: 4.5, 4.6, 5.1 | B35: 4.11 | C35: Fail handling | D35: Failsafe action | E35: 1 | F35: [1] 6.2.10.2 Error handler 6.2.10 Health 5.2.11 Health 6.2.7.5 Version Module (VM) | I35: 1 | J35: [2] 6.2.10.2 Error handler 6.2.10 Health 5.2.11 Health 6.2.7.5 Version Module (VM) | Q35: =IF(OR(ISBLANK(I35),I35="4"),'Bewertung - Assessment'!R35,Titel!H$67) -> - | R35: D2
A36: 4.5, 4.6, 5.1 | B36: 4.12 | C36: Besondere Betriebsmodi | D36: Special operation modes | E36: 1 | F36: [1] 6.2.2.1 System state machine 6.2.2.2 Degraded mode and defect mode 6.2.2.3 HIL mode and development mode | G36: UDS Update, Application, Degraded | I36: 1 | J36: [2] 6.2.2.1 System state machine 6.2.2.2 Degraded mode and defect mode 6.2.2.3 HIL mode and development mode | K36: UDS Update, Application, Degraded | Q36: =IF(OR(ISBLANK(I36),I36="4"),'Bewertung - Assessment'!R36,Titel!H$67) -> - | R36: D2
A37: 4.5, 4.6, 5.1 | B37: 4.13 | C37: Verhalten bei Startup, Shutdown und Reset | D37: Behaviour at Startup, Shutdown and Reset | E37: 2 | F37: [1] 6.1 Overall ECU start-up 6.2.2.1 System state machine 6.2.2.5 State management TDAs and EyeQs 6.2.2.8 Trigger IDC WriteAll (shutdown) 6.2.4.1 Diagnostic Services (Reset) 6.2.7.1 Bootmode CLI | G37: - customer requirements regarding maximum permitted startup and shutdown time? | I37: 2 | J37: [2] 6.1 Overall ECU start-up 6.2.2.1 System state machine 6.2.2.5 State management TDAs and EyeQs 6.2.2.8 Trigger IDC WriteAll (shutdown) 6.2.4.1 Diagnostic Services (Reset) 6.2.7.1 Bootmode CLI | K37: no change | Q37: =IF(OR(ISBLANK(I37),I37="4"),'Bewertung - Assessment'!R37,Titel!H$67) -> - | R37: D3
A38: 4.5, 4.6, 5.1 | B38: 5 | C38: Infrastruktursicht | D38: Infrastructure View
A39: 4.5, 4.6, 5.1 | B39: 5.1 | C39: Hardwarekomponenten und Blockschaltbild | D39: Hardware components and block diagram | E39: 2 | F39: [1] 3.2 Technical Context 3.2.1 Technical Interfaces | G39: in diagram 3.2 Technical Context, ULS is marked as TTTech component? | I39: 2 | J39: [2] 3.2 Technical Context 3.2.1 Technical Interfaces | K39: - No change. - in diagram 3.2 Technical Context, UltraSonic is marked as TTTech component? Is it not part of TDA ECU? | Q39: =IF(OR(ISBLANK(I39),I39="4"),'Bewertung - Assessment'!R39,Titel!H$67) -> - | R39: D3
A40: 4.5, 4.6, 5.1 | B40: 5.2 | C40: MCU-Beschreibung | D40: MCU description | E40: 4 | G40: not documented | I40: 4 | K40: no change | Q40: =IF(OR(ISBLANK(I40),I40="4"),'Bewertung - Assessment'!R40,Titel!H$67) -> D2 | R40: D2
A41: 4.5, 4.6, 5.1 | B41: 5.3 | C41: Peripherie | D41: Peripherals | E41: 2 | F41: [1] Chapter 6 3.2.1 Technical Interfaces | G41: Missing ASIL Rating of external peripherals | I41: 2 | J41: [2] Chapter 6 3.2.1 Technical Interfaces | K41: no change | Q41: =IF(OR(ISBLANK(I41),I41="4"),'Bewertung - Assessment'!R41,Titel!H$67) -> - | R41: D3
...
